Workbook

Sheet Tổng quan
B2: KẾ HOẠCH CÔNG VIỆC - ĐỒ ÁN 1: LAPLACE AI AGENT
B3: Thời gian: 17/08/2026 - 06/12/2026 (dự phòng đến 20/12/2026) | Sprint 2 tuần, báo cáo GV cuối mỗi sprint
B5: Sinh viên thực hiện: Tô Thành Nguyên - 24521207
B6: Cập nhật cột Trạng thái trong sheet Công việc; các bảng dưới đây tự tính tiến độ.
B8: Sprint | C8: Thời gian | D8: Mục tiêu sprint (goal) | E8: Sản phẩm bàn giao | F8: Số task | G8: Hoàn thành | H8: Tiến độ
B9: Sprint 1 | C9: 17/08 - 30/08 | D9: Kiến trúc chốt xong, vòng lặp Agent tối thiểu chạy được ngoại tuyến | E9: Tài liệu kiến trúc; vòng lặp chạy nhiệm vụ mẫu, giải thích được lý do dừng | F9: =COUNTIF('Công việc'!$B:$B,"S1") | G9: =COUNTIFS('Công việc'!$B:$B,"S1",'Công việc'!$H:$H,"Hoàn thành") | H9: =IF(F9=0,0,G9/F9)
B10: Sprint 2 | C10: 31/08 - 13/09 | D10: Bot Telegram nói chuyện bằng mô hình ngôn ngữ thật | E10: Bot chạy thật; theo dõi chi phí; đổi provider bằng cấu hình | F10: =COUNTIF('Công việc'!$B:$B,"S2") | G10: =COUNTIFS('Công việc'!$B:$B,"S2",'Công việc'!$H:$H,"Hoàn thành") | H10: =IF(F10=0,0,G10/F10)
B11: Sprint 3 | C11: 14/09 - 27/09 | D11: Agent giữ ngữ cảnh nhiều lượt, bộ nhớ phiên quản lý được | E11: Context ba tầng; lệnh xem/xóa bộ nhớ; báo cáo thực nghiệm | F11: =COUNTIF('Công việc'!$B:$B,"S3") | G11: =COUNTIFS('Công việc'!$B:$B,"S3",'Công việc'!$H:$H,"Hoàn thành") | H11: =IF(F11=0,0,G11/F11)
B12: Sprint 4 | C12: 28/09 - 11/10 | D12: Ba nhóm công cụ cốt lõi chạy thật qua Telegram (mốc giữa kỳ) | E12: Tool web/tài liệu/nhắc lịch; nhắc đúng hẹn, sống sót sau restart | F12: =COUNTIF('Công việc'!$B:$B,"S4") | G12: =COUNTIFS('Công việc'!$B:$B,"S4",'Công việc'!$H:$H,"Hoàn thành") | H12: =IF(F12=0,0,G12/F12)
B13: Sprint 5 | C13: 12/10 - 25/10 | D13: Mọi hành động nhạy cảm được kiểm soát và chờ duyệt | E13: Approval Gate; chặn vượt quyền + chèn lệnh; báo cáo an toàn | F13: =COUNTIF('Công việc'!$B:$B,"S5") | G13: =COUNTIFS('Công việc'!$B:$B,"S5",'Công việc'!$H:$H,"Hoàn thành") | H13: =IF(F13=0,0,G13/F13)
B14: Sprint 6 | C14: 26/10 - 08/11 | D14: Kết quả có bằng chứng kiểm chứng, hệ thống phục hồi được sau lỗi | E14: Verifier; phân loại lỗi; khôi phục tác vụ sau restart | F14: =COUNTIF('Công việc'!$B:$B,"S6") | G14: =COUNTIFS('Công việc'!$B:$B,"S6",'Công việc'!$H:$H,"Hoàn thành") | H14: =IF(F14=0,0,G14/F14)
B15: Sprint 7 | C15: 09/11 - 22/11 | D15: Đo được chất lượng hệ thống bằng bộ đánh giá định lượng | E15: Đánh giá 1 lệnh; trang quan sát + thống kê; số liệu gốc | F15: =COUNTIF('Công việc'!$B:$B,"S7") | G15: =COUNTIFS('Công việc'!$B:$B,"S7",'Công việc'!$H:$H,"Hoàn thành") | H15: =IF(F15=0,0,G15/F15)
B16: Sprint 8 | C16: 23/11 - 06/12 | D16: Sản phẩm đóng gói hoàn chỉnh, báo cáo sẵn sàng nộp | E16: Docker; báo cáo so sánh; báo cáo cuối kỳ + slide + demo | F16: =COUNTIF('Công việc'!$B:$B,"S8") | G16: =COUNTIFS('Công việc'!$B:$B,"S8",'Công việc'!$H:$H,"Hoàn thành") | H16: =IF(F16=0,0,G16/F16)
B17: Sprint 9 (dự phòng) | C17: 07/12 - 20/12 | D17: Sẵn sàng bảo vệ, xử lý mọi tồn đọng | E17: Sản phẩm + báo cáo ở trạng thái bảo vệ được | F17: =COUNTIF('Công việc'!$B:$B,"S9") | G17: =COUNTIFS('Công việc'!$B:$B,"S9",'Công việc'!$H:$H,"Hoàn thành") | H17: =IF(F17=0,0,G17/F17)
B18: TỔNG | F18: =SUM(F9:F17) | G18: =SUM(G9:G17) | H18: =IF(F18=0,0,G18/F18)

Sheet Công việc
A1: Mã | B1: Sprint | C1: Tuần | D1: Công việc / Task | E1: Mục tiêu / Kết quả mong đợi | F1: Chi tiết kỹ thuật (code gì / cài gì) | G1: Deadline | H1: Trạng thái | I1: Ghi chú
A2: Sprint 1 (17/08 - 30/08)
A3: S1-01 | B3: S1 | C3: Tuần 1 | D3: Nghiên cứu nguyên lý AI Agent (vòng lặp, context, công cụ, xác nhận hành động) | E3: Bản ghi chú chung 5-7 trang làm cơ sở thiết kế | F3: Đọc sổ tay AI Agent trong docs/; ghi chú vào docs/notes.md; chốt từ vựng thống nhất (loop, context, tool, trace, verifier) | G3: 46257 | H3: Chưa làm
A4: S1-02 | B4: S1 | C4: Tuần 1 | D4: Khảo sát 2-3 sản phẩm Agent hiện có | E4: Bảng so sánh cách tổ chức vòng lặp, công cụ, phê duyệt | F4: Khảo sát: OpenAI Agents SDK, LangGraph, Claude Code (cách khai báo tool + approval); lập bảng so sánh trong docs/survey.md | G4: 46257 | H4: Chưa làm
A5: S1-03 | B5: S1 | C5: Tuần 1 | D5: Chốt bản mô tả phạm vi + danh sách việc hệ thống không làm | E5: 1 trang phạm vi được GV thống nhất | F5: Viết docs/scope.md theo mẫu: phục vụ ai / việc gì / nguồn nào / công cụ nào / bằng chứng gì + mục Non-goals | G5: 46257 | H5: Chưa làm
A6: S1-04 | B6: S1 | C6: Tuần 1 | D6: Thiết kế kiến trúc tổng thể | E6: Sơ đồ kiến trúc + mô tả các thành phần chính | F6: Vẽ sơ đồ Mermaid trong docs/architecture.md: Bot ⇄ Backend ⇄ Agent Loop ⇄ (LLM layer | Tool Gateway) ⇄ Storage + Scheduler + Trace Viewer | G6: 46257 | H6: Chưa làm
A7: S1-05 | B7: S1 | C7: Tuần 1 | D7: Thiết kế cơ sở dữ liệu ban đầu | E7: Sơ đồ các bảng dữ liệu chính, đủ cho giai đoạn 1 | F7: Thiết kế bảng: users, conversations, messages, tasks, steps, tool_calls, llm_calls, traces; ERD trong docs/db-design.md | G7: 46257 | H7: Chưa làm
A8: S1-06 | B8: S1 | C8: Tuần 1 | D8: Tìm hiểu Telegram Bot API và cách kết nối mô hình ngôn ngữ | E8: Ghi chú kỹ thuật + demo thử nghiệm nhỏ | F8: Tạo bot qua @BotFather lấy token; đọc docs aiogram v3; viết echo-bot thử nghiệm; thử gọi 1 request tới Gemini (free tier) bằng openai SDK | G8: 46257 | H8: Chưa làm
A9: S1-07 | B9: S1 | C9: Tuần 2 | D9: Khởi tạo dự án: cấu trúc mã nguồn, môi trường, kiểm thử tự động trên GitHub | E9: Repo chạy được, CI xanh | F9: Python ≥3.11, venv, pyproject.toml; cài pytest + ruff; cấu hình .env bằng pydantic-settings; GitHub Actions .github/workflows/ci.yml chạy lint + test | G9: 46264 | H9: Chưa làm
A10: S1-08 | B10: S1 | C10: Tuần 2 | D10: Cài đặt lớp lưu trữ dữ liệu theo thiết kế | E10: Ghi/đọc được các bảng chính, có kiểm thử | F10: Cài SQLAlchemy 2.0 + SQLite; viết laplace/db.py (engine, session) + laplace/models.py (ORM theo ERD); test CRUD cơ bản | G10: 46264 | H10: Chưa làm
A11: S1-09 | B11: S1 | C11: Tuần 2 | D11: Vòng lặp Agent tối thiểu (giới hạn bước) + mô hình giả lập + 1 công cụ đọc | E11: Chạy trọn vòng lặp ngoại tuyến | F11: Viết laplace/agent/loop.py: state machine tối đa 5 bước (nhìn→nghĩ→làm→quan sát→kiểm tra); laplace/llm/mock.py trả kịch bản cố định; tool đọc file laplace/tools/read_file.py | G11: 46264 | H11: Chưa làm
A12: S1-10 | B12: S1 | C12: Tuần 2 | D12: Ghi nhật ký từng bước (mục tiêu, quyết định, công cụ, kết quả, lý do dừng) | E12: Xem lại được toàn bộ diễn biến một nhiệm vụ | F12: Viết laplace/services/trace.py ghi bảng traces (JSON mỗi bước: input, action, tool, result, stop_reason); gắn vào agent loop | G12: 46264 | H12: Chưa làm
A13: S1-11 | B13: S1 | C13: Tuần 2 | D13: Chạy các nhiệm vụ mẫu + giải thích lý do dừng (bàn giao sprint) | E13: 5 nhiệm vụ mẫu hoàn thành, demo cho GV | F13: Script scripts/run_samples.py chạy 5 nhiệm vụ bằng mock; viết README.md hướng dẫn cài + chạy | G13: 46264 | H13: Chưa làm
A14: Sprint 2 (31/08 - 13/09)
A15: S2-01 | B15: S2 | C15: Tuần 1 | D15: Tạo bot Telegram; lớp giao tiếp: tin nhắn, lệnh cơ bản, tệp đính kèm | E15: Bot nhận/gửi được tin nhắn và tệp | F15: Cài aiogram 3.x (polling); laplace/bot/handlers.py: /start /help /status /cancel, handler nhận document; runner khởi động bot + backend cùng lúc | G15: 46271 | H15: Chưa làm
A16: S2-02 | B16: S2 | C16: Tuần 1 | D16: Gắn người dùng với phiên làm việc và tác vụ riêng | E16: Hai người dùng chat song song không lẫn dữ liệu | F16: Middleware aiogram map telegram user_id ↔ bảng users/conversations; mỗi tin nhắn gắn conversation_id; test 2 user song song | G16: 46271 | H16: Chưa làm
A17: S2-03 | B17: S2 | C17: Tuần 1 | D17: Xử lý phản hồi dài, trạng thái đang xử lý, tiến độ từng bước | E17: Trải nghiệm chat mượt, không treo im lặng | F17: Chia tin nhắn >4096 ký tự; gửi 'đang xử lý' + edit_message cập nhật tiến độ từng bước; typing action | G17: 46271 | H17: Chưa làm
A18: S2-04 | B18: S2 | C18: Tuần 1 | D18: Giới hạn tần suất yêu cầu theo người dùng | E18: Spam tin nhắn không làm nghẽn hệ thống | F18: laplace/bot/ratelimit.py: token bucket theo user_id (VD 5 req/phút); tin bị chặn trả thông báo lịch sự | G18: 46271 | H18: Chưa làm
A19: S2-05 | B19: S2 | C19: Tuần 2 | D19: Kết nối mô hình ngôn ngữ thật, đổi nhà cung cấp bằng cấu hình | E19: Đổi provider không sửa mã nguồn | F19: Cài openai SDK; laplace/llm/provider.py dùng base_url + api_key từ .env (Gemini OpenAI-compatible endpoint / OpenAI / Groq); chọn provider qua biến LLM_PROVIDER | G19: 46278 | H19: Chưa làm
A20: S2-06 | B20: S2 | C20: Tuần 2 | D20: Ghi mức sử dụng, chi phí từng lời gọi; thử lại khi dịch vụ quá tải | E20: Có số liệu chi phí cho mọi lời gọi | F20: Ghi bảng llm_calls: tokens in/out, cost ước tính (bảng giá trong config), latency; retry backoff khi HTTP 429/5xx (thư viện tenacity hoặc tự viết) | G20: 46278 | H20: Chưa làm
A21: S2-07 | B21: S2 | C21: Tuần 2 | D21: Chỉ dẫn hệ thống đầu tiên + cơ chế gọi công cụ có kiểm tra dữ liệu | E21: Mô hình chọn và gọi đúng công cụ mẫu | F21: laplace/agent/prompts.py: system prompt v1; tool calling qua JSON schema, validate tham số bằng Pydantic trước khi chạy; sai schema thì yêu cầu mô hình sửa | G21: 46278 | H21: Chưa làm
A22: S2-08 | B22: S2 | C22: Tuần 2 | D22: Kiểm thử toàn tuyến: Telegram → mô hình thật → trả lời (bàn giao sprint) | E22: Demo hội thoại thật cho GV | F22: pytest integration chạy bằng mock (CI không cần key); checklist test tay với model thật; ghi lại 3 hội thoại demo | G22: 46278 | H22: Chưa làm
A23: Sprint 3 (14/09 - 27/09)
A24: S3-01 | B24: S3 | C24: Tuần 1 | D24: Bộ dựng context ba tầng (quy tắc ổn định - nhiệm vụ - diễn biến) | E24: Context mỗi lượt gọn, đúng và đủ | F24: laplace/agent/context.py: ghép 3 tầng (system rules | task card + dữ liệu | tool results mới nhất); đo số token mỗi tầng để theo dõi | G24: 46285 | H24: Chưa làm
A25: S3-02 | B25: S3 | C25: Tuần 1 | D25: Thẻ trạng thái nhiệm vụ cập nhật sau mỗi bước | E25: Nhìn thẻ là biết nhiệm vụ đang ở đâu | F25: Dataclass TaskCard: goal, done_criteria, known/unknown, current_step, tools_used, budget_remaining; serialize vào context + lưu DB | G25: 46285 | H25: Chưa làm
A26: S3-03 | B26: S3 | C26: Tuần 1 | D26: Kiểm soát dung lượng kết quả công cụ (lưu đầy đủ ngoài, nạp tóm tắt) | E26: Kết quả dài không làm phình context | F26: Output tool > ngưỡng (VD 2000 ký tự) → lưu full vào bảng tool_calls, đưa vào context bản tóm tắt + id tham chiếu để đọc lại | G26: 46285 | H26: Chưa làm
A27: S3-04 | B27: S3 | C27: Tuần 2 | D27: Rút gọn context khi hội thoại kéo dài (giữ quyết định, lý do, nguồn) | E27: Hội thoại dài vẫn giữ mạch chính xác | F27: Khi vượt ngưỡng token: gọi LLM tóm tắt lịch sử cũ theo khuôn (quyết định/lý do/kết quả/nguồn), thay thế đoạn cũ; test hội thoại 20+ lượt | G27: 46292 | H27: Chưa làm
A28: S3-05 | B28: S3 | C28: Tuần 2 | D28: Bộ nhớ phiên theo người dùng + lệnh xem/xóa | E28: Người dùng kiểm soát được dữ liệu phiên | F28: Bảng session_memory (user_id, key, value, updated_at); lệnh bot /memory (xem) /clear (xóa); nạp vào context khi liên quan | G28: 46292 | H28: Chưa làm
A29: S3-06 | B29: S3 | C29: Tuần 2 | D29: Thực nghiệm so sánh các cách cấp context (bàn giao sprint) | E29: Báo cáo số liệu chọn phương án hiệu quả | F29: Script chạy 10 nhiệm vụ × 3 cách cấp context (chỉ yêu cầu / kèm dữ liệu thô / kèm tóm tắt cấu trúc); xuất CSV so sánh độ đúng, số lần gọi tool, chi phí | G29: 46292 | H29: Chưa làm
A30: Sprint 4 (28/09 - 11/10)
A31: S4-01 | B31: S4 | C31: Tuần 1 | D31: Cơ chế đăng ký công cụ (tên, công dụng, tham số, kết quả, lúc nào dùng) | E31: Thêm công cụ mới không sửa lõi Agent | F31: laplace/tools/base.py: BaseTool (name, description khi-nào-dùng/không-dùng, args_schema Pydantic, run(), risk_level); registry tự thu thập tool qua decorator | G31: 46299 | H31: Chưa làm
A32: S4-02 | B32: S4 | C32: Tuần 1 | D32: Công cụ tra cứu web: tìm kiếm, thu thập, tóm tắt kèm trích dẫn | E32: Trả lời câu hỏi thực tế có dẫn nguồn | F32: Đăng ký Tavily API key (free tier); laplace/tools/web_search.py + fetch_page.py: httpx tải trang, BeautifulSoup trích nội dung chính; cache kết quả tìm kiếm vào DB; thiếu key → trả kết quả stub | G32: 46299 | H32: Chưa làm
A33: S4-03 | B33: S4 | C33: Tuần 1 | D33: Kiểm thử từng công cụ: thành công / đầu vào sai / dịch vụ lỗi | E33: Mỗi công cụ tối thiểu 3 bài kiểm thử | F33: pytest: mock httpx (respx hoặc monkeypatch); case: 200 OK / tham số sai schema / timeout + 500 | G33: 46299 | H33: Chưa làm
A34: S4-04 | B34: S4 | C34: Tuần 2 | D34: Công cụ xử lý tài liệu: nhận tệp, trích xuất, tóm tắt | E34: Gửi tệp qua Telegram nhận lại tóm tắt đúng | F34: Cài pypdf (PDF) + python-docx (DOCX); tải file qua bot.get_file; laplace/tools/read_document.py; giới hạn ≤10MB, chỉ pdf/docx/txt; tóm tắt bằng LLM giữ trích dẫn trang | G34: 46306 | H34: Chưa làm
A35: S4-05 | B35: S4 | C35: Tuần 2 | D35: Công cụ công việc/nhắc lịch + khôi phục lịch sau khi khởi động lại | E35: Nhắc đúng hẹn, không mất lịch khi restart | F35: Cài APScheduler + SQLAlchemyJobStore (persist job vào SQLite); laplace/tools/reminder.py: create/update/cancel; job đến hạn → gửi tin qua bot; test restart giữ job | G35: 46306 | H35: Chưa làm
A36: S4-06 | B36: S4 | C36: Tuần 2 | D36: Kiểm thử toàn tuyến kịch bản nhiều bước (bàn giao giữa kỳ) | E36: Demo giữa kỳ: 3 nhóm công cụ chạy thật | F36: Kịch bản: 'tìm X rồi tóm tắt rồi đặt nhắc'; chạy end-to-end qua Telegram; quay video demo giữa kỳ | G36: 46306 | H36: Chưa làm
A37: Sprint 5 (12/10 - 25/10)
A38: S5-01 | B38: S5 | C38: Tuần 1 | D38: Phân loại mọi hành động theo mức độ rủi ro | E38: Bảng phân loại rõ ràng, đầy đủ | F38: Enum RiskLevel: READ / DRAFT / WRITE_REVERSIBLE / EXTERNAL_SEND / DESTRUCTIVE gắn vào từng tool; bảng phân loại trong docs/risk-matrix.md | G38: 46313 | H38: Chưa làm
A39: S5-02 | B39: S5 | C39: Tuần 1 | D39: Cổng kiểm soát công cụ: kiểm tra quyền + tham số trước khi chạy | E39: Hành động vượt quyền bị chặn từ lớp thực thi | F39: laplace/agent/gateway.py: mọi tool call đi qua gateway → validate schema, check risk_level vs chính sách; DESTRUCTIVE mặc định từ chối | G39: 46313 | H39: Chưa làm
A40: S5-03 | B40: S5 | C40: Tuần 1 | D40: Approval Gate: nút Xác nhận/Hủy qua Telegram, xử lý hết hạn chờ | E40: Hành động nhạy cảm luôn dừng chờ duyệt | F40: InlineKeyboardMarkup 2 nút + callback handler; lưu approval_state (pending/approved/rejected/expired) vào bảng tasks; timeout 15 phút tự hủy; hiển thị preview nội dung sắp thực hiện | G40: 46313 | H40: Chưa làm
...
